<?xml version="1.0" encoding="utf-8"?>
<!-- This URDF was automatically created by SolidWorks to URDF Exporter! Originally created by Stephen Brawner (brawner@gmail.com) 
     Commit Version: 1.5.1-0-g916b5db  Build Version: 1.5.7152.31018
     For more information, please see http://wiki.ros.org/sw_urdf_exporter -->
<robot
  name="final.SLDASM">
  <link
    name="shoulder_yaw_motor">
    <inertial>
      <origin
        xyz="0.017754 0.029021 0.049066"
        rpy="0 0 0" />
      <mass
        value="0.066398" />
      <inertia
        ixx="1.712E-05"
        ixy="5.4331E-07"
        ixz="-1.0405E-12"
        iyy="2.3578E-05"
        iyz="-2.0422E-11"
        izz="2.6091E-05" />
    </inertial>
    <visual>
      <origin
        xyz="0 0 0"
        rpy="0 0 0" />
      <geometry>
        <mesh
          filename="package://final.SLDASM/meshes/shoulder_yaw_motor.STL" />
      </geometry>
      <material
        name="">
        <color
          rgba="0.79216 0.81961 0.93333 1" />
      </material>
    </visual>
    <collision>
      <origin
        xyz="0 0 0"
        rpy="0 0 0" />
      <geometry>
        <mesh
          filename="package://final.SLDASM/meshes/shoulder_yaw_motor.STL" />
      </geometry>
    </collision>
  </link>
  <link
    name="shoulder_bracket">
    <inertial>
      <origin
        xyz="3.379E-08 0.01072 -0.00020521"
        rpy="0 0 0" />
      <mass
        value="0.034715" />
      <inertia
        ixx="6.5809E-06"
        ixy="1.0525E-11"
        ixz="-2.3966E-13"
        iyy="6.0753E-05"
        iyz="5.6136E-08"
        izz="6.1228E-05" />
    </inertial>
    <visual>
      <origin
        xyz="0 0 0"
        rpy="0 0 0" />
      <geometry>
        <mesh
          filename="package://final.SLDASM/meshes/shoulder_bracket.STL" />
      </geometry>
      <material
        name="">
        <color
          rgba="0.79216 0.81961 0.93333 1" />
      </material>
    </visual>
    <collision>
      <origin
        xyz="0 0 0"
        rpy="0 0 0" />
      <geometry>
        <mesh
          filename="package://final.SLDASM/meshes/shoulder_bracket.STL" />
      </geometry>
    </collision>
  </link>
  <joint
    name="shoulder_yaw"
    type="revolute">
    <origin
      xyz="0.0036685 -0.049066 0.048531"
      rpy="1.5708 0 -1.5666" />
    <parent
      link="shoulder_yaw_motor" />
    <child
      link="shoulder_bracket" />
    <axis
      xyz="0 0 1" />
    <limit
      lower="-3.14"
      upper="3.14"
      effort="0"
      velocity="1" />
  </joint>
  <link
    name="shoulder_pitch_motor">
    <inertial>
      <origin
        xyz="0.020486 0.0026631 0.00031925"
        rpy="0 0 0" />
      <mass
        value="0.15289" />
      <inertia
        ixx="0.00027524"
        ixy="-7.0449E-06"
        ixz="-3.3255E-07"
        iyy="0.00032898"
        iyz="-4.8801E-08"
        izz="7.8237E-05" />
    </inertial>
    <visual>
      <origin
        xyz="0 0 0"
        rpy="0 0 0" />
      <geometry>
        <mesh
          filename="package://final.SLDASM/meshes/shoulder_pitch_motor.STL" />
      </geometry>
      <material
        name="">
        <color
          rgba="0.79216 0.81961 0.93333 1" />
      </material>
    </visual>
    <collision>
      <origin
        xyz="0 0 0"
        rpy="0 0 0" />
      <geometry>
        <mesh
          filename="package://final.SLDASM/meshes/shoulder_pitch_motor.STL" />
      </geometry>
    </collision>
  </link>
  <joint
    name="shoulder_pitch"
    type="revolute">
    <origin
      xyz="0 0.0466 -0.0005"
      rpy="-1.5708 -0.10745 1.5708" />
    <parent
      link="shoulder_bracket" />
    <child
      link="shoulder_pitch_motor" />
    <axis
      xyz="0 0 1" />
    <limit
      lower="-2.09"
      upper="2.09"
      effort="0"
      velocity="1" />
  </joint>
  <link
    name="biscep">
    <inertial>
      <origin
        xyz="0.0181329751786151 -0.106301122463918 2.8277577882453E-07"
        rpy="0 0 0" />
      <mass
        value="0.0184730318277506" />
      <inertia
        ixx="2.07474912409545E-05"
        ixy="1.43500998725713E-19"
        ixz="5.83883633344031E-19"
        iyy="5.70639971271242E-06"
        iyz="4.18009601528211E-17"
        izz="2.3519532396151E-05" />
    </inertial>
    <visual>
      <origin
        xyz="0 0 0"
        rpy="0 0 0" />
      <geometry>
        <mesh
          filename="package://final.SLDASM/meshes/biscep.STL" />
      </geometry>
      <material
        name="">
        <color
          rgba="0.792156862745098 0.819607843137255 0.933333333333333 1" />
      </material>
    </visual>
    <collision>
      <origin
        xyz="0 0 0"
        rpy="0 0 0" />
      <geometry>
        <mesh
          filename="package://final.SLDASM/meshes/biscep.STL" />
      </geometry>
    </collision>
  </link>
  <joint
    name="sp_bis"
    type="fixed">
    <origin
      xyz="0 0 0.017733"
      rpy="1.7023 1.5708 0" />
    <parent
      link="shoulder_pitch_motor" />
    <child
      link="biscep" />
    <axis
      xyz="0 0 0" />
  </joint>
  <link
    name="elbow_bracket">
    <inertial>
      <origin
        xyz="1.38777878078145E-17 -9.10729824887824E-18 -0.00859778225993391"
        rpy="0 0 0" />
      <mass
        value="0.00712469723330028" />
      <inertia
        ixx="1.74510872895828E-06"
        ixy="-7.19357619706741E-21"
        ixz="-1.59320155856542E-21"
        iyy="3.79921818211563E-06"
        iyz="8.0493266505478E-22"
        izz="3.5752069366271E-06" />
    </inertial>
    <visual>
      <origin
        xyz="0 0 0"
        rpy="0 0 0" />
      <geometry>
        <mesh
          filename="package://final.SLDASM/meshes/elbow_bracket.STL" />
      </geometry>
      <material
        name="">
        <color
          rgba="0.792156862745098 0.819607843137255 0.933333333333333 1" />
      </material>
    </visual>
    <collision>
      <origin
        xyz="0 0 0"
        rpy="0 0 0" />
      <geometry>
        <mesh
          filename="package://final.SLDASM/meshes/elbow_bracket.STL" />
      </geometry>
    </collision>
  </link>
  <joint
    name="bis_el"
    type="fixed">
    <origin
      xyz="0.018133 -0.1563 0"
      rpy="1.5708 0 -3.1416" />
    <parent
      link="biscep" />
    <child
      link="elbow_bracket" />
    <axis
      xyz="0 0 0" />
  </joint>
  <link
    name="elbow_motor">
    <inertial>
      <origin
        xyz="0.0153959891257165 0.00198308026636963 -0.000474094845054979"
        rpy="0 0 0" />
      <mass
        value="0.0665737596498169" />
      <inertia
        ixx="1.58621578388763E-05"
        ixy="-1.82446071337361E-06"
        ixz="-4.42877610317752E-07"
        iyy="3.02577276828313E-05"
        iyz="-6.14267578542797E-08"
        izz="2.47834410363908E-05" />
    </inertial>
    <visual>
      <origin
        xyz="0 0 0"
        rpy="0 0 0" />
      <geometry>
        <mesh
          filename="package://final.SLDASM/meshes/elbow_motor.STL" />
      </geometry>
      <material
        name="">
        <color
          rgba="0.792156862745098 0.819607843137255 0.933333333333333 1" />
      </material>
    </visual>
    <collision>
      <origin
        xyz="0 0 0"
        rpy="0 0 0" />
      <geometry>
        <mesh
          filename="package://final.SLDASM/meshes/elbow_motor.STL" />
      </geometry>
    </collision>
  </link>
  <joint
    name="br_el"
    type="revolute">
    <origin
      xyz="0 0 -0.0366"
      rpy="-1.5708 1.1938 -1.5708" />
    <parent
      link="elbow_bracket" />
    <child
      link="elbow_motor" />
    <axis
      xyz="0 0 1" />
    <limit
      lower="-2.09"
      upper="2.09"
      effort="0"
      velocity="1" />
  </joint>
  <link
    name="forearm">
    <inertial>
      <origin
        xyz="0.0182066844425551 -0.100301122463916 2.82775761459297E-07"
        rpy="0 0 0" />
      <mass
        value="0.0184730318277506" />
      <inertia
        ixx="2.07474912409546E-05"
        ixy="1.55702274652388E-19"
        ixz="5.75254485193878E-20"
        iyy="5.70639971271241E-06"
        iyz="4.06630907059591E-17"
        izz="2.35195323961511E-05" />
    </inertial>
    <visual>
      <origin
        xyz="0 0 0"
        rpy="0 0 0" />
      <geometry>
        <mesh
          filename="package://final.SLDASM/meshes/forearm.STL" />
      </geometry>
      <material
        name="">
        <color
          rgba="0.792156862745098 0.819607843137255 0.933333333333333 1" />
      </material>
    </visual>
    <collision>
      <origin
        xyz="0 0 0"
        rpy="0 0 0" />
      <geometry>
        <mesh
          filename="package://final.SLDASM/meshes/forearm.STL" />
      </geometry>
    </collision>
  </link>
  <joint
    name="el_for"
    type="fixed">
    <origin
      xyz="0 0 0.016907"
      rpy="1.7023 1.5708 0" />
    <parent
      link="elbow_motor" />
    <child
      link="forearm" />
    <axis
      xyz="0 0 0" />
  </joint>
  <link
    name="wrist_bracket">
    <inertial>
      <origin
        xyz="0.000591190782544812 -0.0316940613718485 -9.79596658859383E-08"
        rpy="0 0 0" />
      <mass
        value="0.0181317732136276" />
      <inertia
        ixx="1.29575470819088E-05"
        ixy="1.20144015050604E-07"
        ixz="-2.14399176538841E-11"
        iyy="8.2263100626073E-06"
        iyz="-3.16685269207755E-11"
        izz="7.32089034975683E-06" />
    </inertial>
    <visual>
      <origin
        xyz="0 0 0"
        rpy="0 0 0" />
      <geometry>
        <mesh
          filename="package://final.SLDASM/meshes/wrist_bracket.STL" />
      </geometry>
      <material
        name="">
        <color
          rgba="0.752941176470588 0.752941176470588 0.752941176470588 1" />
      </material>
    </visual>
    <collision>
      <origin
        xyz="0 0 0"
        rpy="0 0 0" />
      <geometry>
        <mesh
          filename="package://final.SLDASM/meshes/wrist_bracket.STL" />
      </geometry>
    </collision>
  </link>
  <joint
    name="for_wb"
    type="fixed">
    <origin
      xyz="0.018207 -0.2008 0"
      rpy="1.5728 -1.5708 1.5688" />
    <parent
      link="forearm" />
    <child
      link="wrist_bracket" />
    <axis
      xyz="0 0 0" />
  </joint>
  <link
    name="wrist_pitch_motor">
    <inertial>
      <origin
        xyz="0.00138267310715295 0.0217129052134361 -0.021214784036667"
        rpy="0 0 0" />
      <mass
        value="0.00791913116558566" />
      <inertia
        ixx="4.75252919647101E-06"
        ixy="-1.72103065369274E-07"
        ixz="-1.70972037922435E-08"
        iyy="2.05723124150455E-06"
        iyz="-2.68535181372705E-07"
        izz="3.44060300617436E-06" />
    </inertial>
    <visual>
      <origin
        xyz="0 0 0"
        rpy="0 0 0" />
      <geometry>
        <mesh
          filename="package://final.SLDASM/meshes/wrist_pitch_motor.STL" />
      </geometry>
      <material
        name="">
        <color
          rgba="0.792156862745098 0.819607843137255 0.933333333333333 1" />
      </material>
    </visual>
    <collision>
      <origin
        xyz="0 0 0"
        rpy="0 0 0" />
      <geometry>
        <mesh
          filename="package://final.SLDASM/meshes/wrist_pitch_motor.STL" />
      </geometry>
    </collision>
  </link>
  <joint
    name="br_ptch"
    type="revolute">
    <origin
      xyz="0 0 0.01908"
      rpy="0 0 0" />
    <parent
      link="wrist_bracket" />
    <child
      link="wrist_pitch_motor" />
    <axis
      xyz="0 0 1" />
    <limit
      lower="-1.13"
      upper="2.1816"
      effort="0"
      velocity="1" />
  </joint>
  <link
    name="square_plate">
    <inertial>
      <origin
        xyz="0.017622178318782 0.0210000000686168 -0.0138768952454561"
        rpy="0 0 0" />
      <mass
        value="0.0138784016209193" />
      <inertia
        ixx="6.67876634868717E-06"
        ixy="8.914313923484E-15"
        ixz="4.28468788736982E-07"
        iyy="4.12299172706325E-06"
        iyz="-1.27104315307768E-14"
        izz="5.93925406672571E-06" />
    </inertial>
    <visual>
      <origin
        xyz="0 0 0"
        rpy="0 0 0" />
      <geometry>
        <mesh
          filename="package://final.SLDASM/meshes/square_plate.STL" />
      </geometry>
      <material
        name="">
        <color
          rgba="0.792156862745098 0.819607843137255 0.933333333333333 1" />
      </material>
    </visual>
    <collision>
      <origin
        xyz="0 0 0"
        rpy="0 0 0" />
      <geometry>
        <mesh
          filename="package://final.SLDASM/meshes/square_plate.STL" />
      </geometry>
    </collision>
  </link>
  <joint
    name="pitch_plate"
    type="fixed">
    <origin
      xyz="0.032049 0.070607 0.00116"
      rpy="-1.5708 0 -1.6343" />
    <parent
      link="wrist_pitch_motor" />
    <child
      link="square_plate" />
    <axis
      xyz="0 0 0" />
  </joint>
  <link
    name="wrist_yaw_motor">
    <inertial>
      <origin
        xyz="-9.59261514520138E-07 -0.021756885137284 0.00137478433804583"
        rpy="0 0 0" />
      <mass
        value="0.00791913113681829" />
      <inertia
        ixx="4.76355705075102E-06"
        ixy="-1.04448472767812E-10"
        ixz="-1.37428428510361E-11"
        iyy="2.04620312855865E-06"
        iyz="-2.69079685868104E-07"
        izz="3.44060277118967E-06" />
    </inertial>
    <visual>
      <origin
        xyz="0 0 0"
        rpy="0 0 0" />
      <geometry>
        <mesh
          filename="package://final.SLDASM/meshes/wrist_yaw_motor.STL" />
      </geometry>
      <material
        name="">
        <color
          rgba="0.792156862745098 0.819607843137255 0.933333333333333 1" />
      </material>
    </visual>
    <collision>
      <origin
        xyz="0 0 0"
        rpy="0 0 0" />
      <geometry>
        <mesh
          filename="package://final.SLDASM/meshes/wrist_yaw_motor.STL" />
      </geometry>
    </collision>
  </link>
  <joint
    name="square_yaw"
    type="fixed">
    <origin
      xyz="0.0125 0.021 0.0435"
      rpy="1.5708 0 1.5708" />
    <parent
      link="square_plate" />
    <child
      link="wrist_yaw_motor" />
    <axis
      xyz="0 0 0" />
  </joint>
  <link
    name="wrist_roll_motor">
    <inertial>
      <origin
        xyz="9.53316816876271E-07 0.0197431148165101 0.00137478397749273"
        rpy="0 0 0" />
      <mass
        value="0.00791913113244744" />
      <inertia
        ixx="4.76355706993376E-06"
        ixy="-1.83616126961688E-10"
        ixz="7.08006792659656E-12"
        iyy="2.0462031355888E-06"
        iyz="-2.69079733566402E-07"
        izz="3.44060278316954E-06" />
    </inertial>
    <visual>
      <origin
        xyz="0 0 0"
        rpy="0 0 0" />
      <geometry>
        <mesh
          filename="package://final.SLDASM/meshes/wrist_roll_motor.STL" />
      </geometry>
      <material
        name="">
        <color
          rgba="0.752941176470588 0.752941176470588 0.752941176470588 1" />
      </material>
    </visual>
    <collision>
      <origin
        xyz="0 0 0"
        rpy="0 0 0" />
      <geometry>
        <mesh
          filename="package://final.SLDASM/meshes/wrist_roll_motor.STL" />
      </geometry>
    </collision>
  </link>
  <joint
    name="yaw_roll"
    type="revolute">
    <origin
      xyz="0 0 0.02024"
      rpy="1.5708 0 -0.44644" />
    <parent
      link="wrist_yaw_motor" />
    <child
      link="wrist_roll_motor" />
    <axis
      xyz="0 0 1" />
    <limit
      lower="-2.618"
      upper="2.618"
      effort="0"
      velocity="1" />
  </joint>
</robot>