<?xml version="1.0" ?>
<!-- =================================================================================== -->
<!-- |    This document was autogenerated by xacro from mobile_manipulator.xacro       | -->
<!-- |    EDITING THIS FILE BY HAND IS NOT RECOMMENDED                                 | -->
<!-- =================================================================================== -->
<robot name="mobile_manipulator" xmlns:xacro="http://www.ros.org/wiki/xacro">
  <material name="orange">
    <color rgba="1 0.487 0 1"/>
  </material>
  <material name="white">
    <color rgba="1 1 1 1"/>
  </material>
  <material name="green">
    <color rgba="0 0.8 0 1"/>
  </material>
  
============================================================================================================================================

  


=============================================================================================================================================

  <!-- LINKS -->
  <link name="bot">
    <visual>
      <origin rpy="0 0 -1.57" xyz="0 0 0"/>
      <geometry>
        <mesh filename="package://mobile_manipulator/meshes/bot.stl" scale="0.001 0.001 0.001"/>
      </geometry>
      <material name="green"/>
    </visual>
    <collision>
      <origin rpy="0 0 -1.57" xyz="0 0 0"/>
      <geometry>
        <mesh filename="package://mobile_manipulator/meshes/bot.stl" scale="0.001 0.001 0.001"/>
      </geometry>
    </collision>
  </link>
  <link name="shoulder_yaw_motor">
    <inertial>
      <origin rpy="0 0 0 " xyz="0.13 -0.02 0.1715"/>
      <mass value="0.140"/>
      <inertia ixx="0.000050799110" ixy="0.0" ixz="0.0" iyy="0.00002857215" iyz="0.00000051457" izz="0.000043394"/>
    </inertial>
    <visual>
      <origin rpy="0 0 0 " xyz="0.13 -0.02 0.1715"/>
      <geometry>
        <mesh filename="package://mobile_manipulator/meshes/base_motor.STL" scale="0.001 0.001 0.001"/>
      </geometry>
      <material name="white"/>
    </visual>
    <collision>
      <origin rpy="0 0 0" xyz="0.13 -0.02 0.1715"/>
      <geometry>
        <mesh filename="package://mobile_manipulator/meshes/shoulder_yaw.STL" scale="0.001 0.001 0.001"/>
      </geometry>
    </collision>
  </link>
  <link name="shoulder_bracket">
    <inertial>
      <origin rpy="0 0 0 " xyz="-0.019 -0.062 0.0"/>
      <mass value="0.140"/>
      <inertia ixx="0.000050799110" ixy="0.0" ixz="0.0" iyy="0.00002857215" iyz="0.00000051457" izz="0.000043394"/>
    </inertial>
    <visual>
      <origin rpy="0 0 0 " xyz="-0.019 -0.062 0"/>
      <geometry>
        <mesh filename="package://mobile_manipulator/meshes/shoulder_yaw1.STL" scale="0.001 0.001 0.001"/>
      </geometry>
      <material name="white"/>
    </visual>
    <collision>
      <origin rpy="0 0 0 " xyz="-0.019 -0.062 0"/>
      <geometry>
        <mesh filename="package://mobile_manipulator/meshes/shoulder_yaw1.STL" scale="0.001 0.001 0.001"/>
      </geometry>
    </collision>
  </link>
  <link name="shoulder_pitch_motor">
    <inertial>
      <origin rpy="-1.57 3.14 1.57" xyz="0.09 0 -0.00120"/>
      <mass value="0.140"/>
      <inertia ixx="0.000050799110" ixy="0.0" ixz="0.0" iyy="0.00002857215" iyz="0.00000051457" izz="0.000043394"/>
    </inertial>
    <visual>
      <origin rpy="-1.57 3.14 1.57" xyz="0.09 0.06 -0.0120"/>
      <geometry>
        <mesh filename="package://mobile_manipulator/meshes/shoulder_pitch.STL" scale="0.001 0.001 0.001"/>
      </geometry>
      <material name="white"/>
    </visual>
    <collision>
      <origin rpy="-1.57 3.14 1.57" xyz="0.09 0 -0.0120"/>
      <geometry>
        <mesh filename="package://mobile_manipulator/meshes/shoulder_pitch.STL" scale="0.001 0.001 0.001"/>
      </geometry>
    </collision>
  </link>
  <link name="elbow_motor">
    <inertial>
      <origin rpy="-1.57 3.14 0" xyz="0.0180 -0.09 -0.02"/>
      <mass value="0.140"/>
      <inertia ixx="0.000050799110" ixy="0.0" ixz="0.0" iyy="0.00002857215" iyz="0.00000051457" izz="0.000043394"/>
    </inertial>
    <visual>
      <origin rpy="-1.57 3.14 0" xyz="0.0180 -0.09 -0.02"/>
      <geometry>
        <mesh filename="package://mobile_manipulator/meshes/elbow_pitch.STL" scale="0.001 0.001 0.001"/>
      </geometry>
      <material name="orange"/>
    </visual>
    <collision>
      <origin rpy="-1.57 3.14 0" xyz="0.0180 -0.09 -0.02"/>
      <geometry>
        <mesh filename="package://mobile_manipulator/meshes/elbow_pitch.STL" scale="0.001 0.001 0.001"/>
      </geometry>
    </collision>
  </link>
  <link name="wrist_pitch_motor">
    <inertial>
      <origin rpy="-1.57 0 1.57" xyz="0.0090 -0.05 -0.009"/>
      <mass value="0.140"/>
      <inertia ixx="0.000050799110" ixy="0.0" ixz="0.0" iyy="0.00002857215" iyz="0.00000051457" izz="0.000043394"/>
    </inertial>
    <visual>
      <origin rpy="-1.57 3.14 0" xyz="0.0090 -0.05 -0.009"/>
      <geometry>
        <mesh filename="package://mobile_manipulator/meshes/wrist_pitch.STL" scale="0.001 0.001 0.001"/>
      </geometry>
      <material name="orange"/>
    </visual>
    <collision>
      <origin rpy="-1.57 0 1.57" xyz="0.0090 -0.05 -0.009"/>
      <geometry>
        <mesh filename="package://mobile_manipulator/meshes/wrist_pitch.STL" scale="0.001 0.001 0.001"/>
      </geometry>
    </collision>
  </link>
  <link name="wrist_yaw_motor">
    <inertial>
      <origin rpy="0 0 3.14" xyz="0.02 -0.055 -0.063"/>
      <mass value="0.140"/>
      <inertia ixx="0.000050799110" ixy="0.0" ixz="0.0" iyy="0.00002857215" iyz="0.00000051457" izz="0.000043394"/>
    </inertial>
    <visual>
      <origin rpy="1.57 0 3.14" xyz="0.02 -0.055 -0.063"/>
      <geometry>
        <mesh filename="package://mobile_manipulator/meshes/wrist_yaw.STL" scale="0.001 0.001 0.001"/>
      </geometry>
      <material name="orange"/>
    </visual>
    <collision>
      <origin rpy="0 0 3.14" xyz="0.02 -0.055 -0.063"/>
      <geometry>
        <mesh filename="package://mobile_manipulator/meshes/wrist_yaw.STL" scale="0.001 0.001 0.001"/>
      </geometry>
    </collision>
  </link>
  <link name="wrist_roll_motor">
    <inertial>
      <origin rpy="-1.57 3.14 0" xyz="-0.02 -0.06 -0.026"/>
      <mass value="0.140"/>
      <inertia ixx="0.000050799110" ixy="0.0" ixz="0.0" iyy="0.00002857215" iyz="0.00000051457" izz="0.000043394"/>
    </inertial>
    <visual>
      <origin rpy="-1.57 3.14 0" xyz="-0.02 -0.06 -0.026"/>
      <geometry>
        <mesh filename="package://mobile_manipulator/meshes/wrist_roll.STL" scale="0.001 0.001 0.001"/>
      </geometry>
      <material name="orange"/>
    </visual>
    <collision>
      <origin rpy="-1.57 3.14 0" xyz="-0.02 -0.06 -0.026"/>
      <geometry>
        <mesh filename="package://mobile_manipulator/meshes/wrist_roll.STL" scale="0.001 0.001 0.001"/>
      </geometry>
    </collision>
  </link>
  <joint name="bot_joint" type="fixed">
    <origin rpy="0 0 0" xyz="0 0 0"/>
    <parent link="bot"/>
    <child link="shoulder_yaw_motor"/>
  </joint>
  <joint name="shoulder_yaw" type="revolute">
    <origin rpy="0 0 0" xyz="0.1765 -0.003 0.26"/>
    <parent link="shoulder_yaw_motor"/>
    <child link="shoulder_bracket"/>
    <axis xyz="0 0 1"/>
    <limit effort="30" lower="-3.14" upper="3.14" velocity="1.0"/>
  </joint>
  <joint name="shoulder_pitch" type="revolute">
    <origin rpy="0 0 0.0" xyz="0 0.010 0.040"/>
    <parent link="shoulder_bracket"/>
    <child link="shoulder_pitch_motor"/>
    <axis xyz="0 1 0"/>
    <limit effort="30" lower="-1.6592" upper="1.727" velocity="1.0"/>
  </joint>
  <joint name="elbow" type="revolute">
    <origin rpy="0 0 0" xyz="-0.002 0 0.2"/>
    <parent link="shoulder_pitch_motor"/>
    <child link="elbow_motor"/>
    <axis xyz="0 1 0"/>
    <limit effort="30" lower="-1.9262" upper="1.934" velocity="1.0"/>
  </joint>
  <joint name="wrist_pitch" type="revolute">
    <origin rpy="0 0 0" xyz="0.004 0 0.196 "/>
    <parent link="elbow_motor"/>
    <child link="wrist_pitch_motor"/>
    <axis xyz="0 1 0"/>
    <limit effort="30" lower="-2.29" upper="0.718" velocity="1.0"/>
  </joint>
  <joint name="wrist_yaw" type="revolute">
    <origin rpy="0 0 0" xyz="-0.080 0 0.05"/>
    <parent link="wrist_pitch_motor"/>
    <child link="wrist_yaw_motor"/>
    <axis xyz="0 0 1"/>
    <limit effort="30" lower="-1.43" upper="+2.11" velocity="1.0"/>
  </joint>
  <joint name="wrist_roll" type="revolute">
    <origin rpy="0 0 0" xyz="0 0 -0.0415"/>
    <parent link="wrist_yaw_motor"/>
    <child link="wrist_roll_motor"/>
    <axis xyz="1 0 0"/>
    <limit effort="30" lower="-2.617" upper="+2.617" velocity="1.0"/>
  </joint>
</robot>

