<?xml version="1.0" ?>
<!-- =================================================================================== -->
<!-- |    This document was autogenerated by xacro from obj_recognition.urdf.xacro     | -->
<!-- |    EDITING THIS FILE BY HAND IS NOT RECOMMENDED                                 | -->
<!-- =================================================================================== -->
<robot name="pcl_ros_cluster_segmentation" xmlns:xacro="http://www.ros.org/wiki/xacro">
  <!-- ros_control plugin -->
  <gazebo>
    <plugin filename="libgazebo_ros_control.so" name="gazebo_ros_control">
      <robotNamespace>/pcl_ros_cluster_segmentation</robotNamespace>
      <robotSimType>gazebo_ros_control/DefaultRobotHWSim</robotSimType>
    </plugin>
  </gazebo>
  <!--base_link-->
  <gazebo reference="base_link">
    <material>Gazebo/White</material>
  </gazebo>
  <!--link_1-->
  <gazebo reference="link_1">
    <mu1>0.2</mu1>
    <mu2>0.2</mu2>
    <material>Gazebo/Orange</material>
  </gazebo>
  <!--link_2-->
  <gazebo reference="link_2">
    <mu1>0.2</mu1>
    <mu2>0.2</mu2>
    <material>Gazebo/White</material>
  </gazebo>
  <!--camera_link-->
  <gazebo reference="camera_link">
    <mu1>0.2</mu1>
    <mu2>0.2</mu2>
    <material>Gazebo/Grey</material>
  </gazebo>
  <!--RGBD camera -->
  <gazebo reference="camera_rgb_frame">
    <sensor name="camera" type="depth">
      <always_on>true</always_on>
      <visualize>false</visualize>
      <update_rate>15.0</update_rate>
      <camera name="front">
        <horizontal_fov>1.047197</horizontal_fov>
        <image>
          <!-- openni_kinect plugin works only with BGR8 -->
          <format>B8G8R8</format>
          <width>640</width>
          <height>480</height>
        </image>
        <clip>
          <near>0.01</near>
          <far>9</far>
        </clip>
      </camera>
      <plugin filename="libgazebo_ros_openni_kinect.so" name="camera_controller">
        <baseline>0.1</baseline>
        <alwaysOn>true</alwaysOn>
        <updateRate>15.0</updateRate>
        <cameraName>camera</cameraName>
        <imageTopicName>/camera/rgb/image_raw</imageTopicName>
        <cameraInfoTopicName>/camera/rgb/camera_info</cameraInfoTopicName>
        <depthImageTopicName>/camera/depth_registered/image_raw</depthImageTopicName>
        <depthImageCameraInfoTopicName>/camera/depth_registered/camera_info</depthImageCameraInfoTopicName>
        <pointCloudTopicName>/camera/depth_registered/points</pointCloudTopicName>
        <frameName>camera_rgb_optical_frame</frameName>
        <pointCloudCutoff>0.35</pointCloudCutoff>
        <pointCloudCutoffMax>4.5</pointCloudCutoffMax>
        <CxPrime>0</CxPrime>
        <Cx>0</Cx>
        <Cy>0</Cy>
        <focalLength>0</focalLength>
        <hackBaseline>0</hackBaseline>
      </plugin>
    </sensor>
  </gazebo>
  <!--Links-->
  <link name="world"/>
  <link name="link_1">
    <visual>
      <origin rpy="0 0 0" xyz="0 0 0"/>
      <geometry>
        <box size="0.1 0.1 1.5"/>
      </geometry>
      <material name="blue">
        <color rgba="0.0 0.0 0.8 1.0"/>
      </material>
    </visual>
    <collision>
      <origin rpy="0 0 0" xyz="0 0 0"/>
      <geometry>
        <box size="0.1 0.1 1.5"/>
      </geometry>
    </collision>
    <inertial>
      <origin rpy="0 0 0" xyz="0 0 0"/>
      <mass value="10"/>
      <inertia ixx="1.88333333333" ixy="0.0" ixz="0.0" iyy="1.88333333333" iyz="0.0" izz="0.0166666666667"/>
    </inertial>
  </link>
  <link name="link_2">
    <visual>
      <origin rpy="0 0 0" xyz="0 0 0"/>
      <geometry>
        <box size="0.1 0.1 0.1"/>
      </geometry>
      <material name="white">
        <color rgba="1.0 1.0 1.0 1.0"/>
      </material>
    </visual>
    <collision>
      <origin rpy="0 0 0" xyz="0 0 0"/>
      <geometry>
        <box size="0.1 0.1 0.1"/>
      </geometry>
    </collision>
    <inertial>
      <origin rpy="0 0 0" xyz="0 0 0"/>
      <mass value="1"/>
      <inertia ixx="0.00166666666667" ixy="0.0" ixz="0.0" iyy="0.00166666666667" iyz="0.0" izz="0.00166666666667"/>
    </inertial>
  </link>
  <!-- RGBD camera -->
  <link name="camera_link">
    <collision>
      <origin rpy="0 0 0" xyz="-0.016 0 0"/>
      <geometry>
        <box size="0.036 0.18 0.04"/>
      </geometry>
    </collision>
    <visual>
      <origin rpy="0 0 0" xyz="0 0 0"/>
      <geometry>
        <mesh filename="/home/avitra/manipulator_ws/src/pcl_ros_cluster_segmentation/meshes/asus_xtion.dae"/>
      </geometry>
    </visual>
    <inertial>
      <mass value="0.2"/>
      <origin rpy="0 0 0" xyz="0 0 0"/>
      <inertia ixx="5.8083e-4" ixy="0" ixz="0" iyy="3.0833e-5" iyz="0" izz="5.9083e-4"/>
    </inertial>
  </link>
  <!--Joints-->
  <joint name="fixed_base_joint" type="fixed">
    <parent link="world"/>
    <child link="link_1"/>
    <origin rpy="0 0 0" xyz="0 0 0.75"/>
  </joint>
  <joint name="pan_joint" type="continuous">
    <parent link="link_1"/>
    <child link="link_2"/>
    <axis xyz="0 0 1"/>
    <origin rpy="0 0 -1.57079632679" xyz="0 0 0.8"/>
  </joint>
  <joint name="tilt_joint" type="continuous">
    <origin rpy="0 0.5 0" xyz="0.05 0 0.07"/>
    <parent link="link_2"/>
    <child link="camera_link"/>
    <axis xyz="0 1 0"/>
  </joint>
  <link name="camera_rgb_frame"/>
  <joint name="camera_rgb_joint" type="fixed">
    <origin rpy="0 0 0" xyz="0 0.022 0"/>
    <parent link="camera_link"/>
    <child link="camera_rgb_frame"/>
  </joint>
  <link name="camera_rgb_optical_frame"/>
  <joint name="camera_rgb_optical_joint" type="fixed">
    <origin rpy="-1.57079632679 0 -1.57079632679" xyz="0 0 0"/>
    <parent link="camera_rgb_frame"/>
    <child link="camera_rgb_optical_frame"/>
  </joint>
  <link name="camera_depth_frame"/>
  <joint name="camera_depth_joint" type="fixed">
    <origin rpy="0 0 0" xyz="0 0.049 0"/>
    <parent link="camera_link"/>
    <child link="camera_depth_frame"/>
  </joint>
  <link name="camera_depth_optical_frame"/>
  <joint name="camera_depth_optical_joint" type="fixed">
    <origin rpy="-1.57079632679 0 -1.57079632679" xyz="0 0 0"/>
    <parent link="camera_depth_frame"/>
    <child link="camera_depth_optical_frame"/>
  </joint>
  <!--Transmission and actuators-->
  <transmission name="tran1">
    <type>transmission_interface/SimpleTransmission</type>
    <joint name="pan_joint">
      <hardwareInterface>hardware_interface/PositionJointInterface</hardwareInterface>
    </joint>
    <actuator name="motor1">
      <hardwareInterface>hardware_interface/PositionJointInterface</hardwareInterface>
      <mechanicalReduction>1</mechanicalReduction>
    </actuator>
  </transmission>
  <transmission name="tran2">
    <type>transmission_interface/SimpleTransmission</type>
    <joint name="tilt_joint">
      <hardwareInterface>hardware_interface/PositionJointInterface</hardwareInterface>
    </joint>
    <actuator name="motor2">
      <hardwareInterface>hardware_interface/PositionJointInterface</hardwareInterface>
      <mechanicalReduction>1</mechanicalReduction>
    </actuator>
  </transmission>
</robot>
